[UID:2390][3033523] Child process with pid: 3033526 was killed by signal: 15, core dump: 0
[UID:2390][3033523] Child process with pid: 3037659 was killed by signal: 15, core dump: 0
Traceback (most recent call last):
  File "/home/convertimageio/public_html/app-flask/passenger_wsgi.py", line 8, in <module>
    wsgi = imp.load_source('wsgi', 'main.py')
  File "/opt/alt/python37/lib64/python3.7/imp.py", line 171, in load_source
    module = _load(spec)
  File "<frozen importlib._bootstrap>", line 696, in _load
  File "<frozen importlib._bootstrap>", line 677, in _load_unlocked
  File "<frozen importlib._bootstrap_external>", line 728, in exec_module
  File "<frozen importlib._bootstrap>", line 219, in _call_with_frames_removed
  File "main.py", line 1, in <module>
    from flask import Flask, jsonify, redirect, request, json, flash, render_template, send_from_directory, url_for
ModuleNotFoundError: No module named 'flask'
[UID:2390][3038201] Child process with pid: 3038213 was killed by signal: 15, core dump: 0
Traceback (most recent call last):
  File "/home/convertimageio/public_html/app-flask/passenger_wsgi.py", line 8, in <module>
    wsgi = imp.load_source('wsgi', 'main.py')
  File "/opt/alt/python37/lib64/python3.7/imp.py", line 171, in load_source
    module = _load(spec)
  File "<frozen importlib._bootstrap>", line 696, in _load
  File "<frozen importlib._bootstrap>", line 677, in _load_unlocked
  File "<frozen importlib._bootstrap_external>", line 728, in exec_module
  File "<frozen importlib._bootstrap>", line 219, in _call_with_frames_removed
  File "main.py", line 1, in <module>
    from flask import Flask
ModuleNotFoundError: No module named 'flask'
[UID:2390][3041892] Child process with pid: 3041898 was killed by signal: 15, core dump: 0
[UID:2390][3041892] Child process with pid: 3042172 was killed by signal: 15, core dump: 0
[UID:2390][3041892] Child process with pid: 3042326 was killed by signal: 15, core dump: 0
[UID:2390][3041892] Child process with pid: 3043290 was killed by signal: 15, core dump: 0
Traceback (most recent call last):
  File "/home/convertimageio/public_html/app-flask/passenger_wsgi.py", line 8, in <module>
    wsgi = imp.load_source('wsgi', 'main.py')
  File "/opt/alt/python37/lib64/python3.7/imp.py", line 171, in load_source
    module = _load(spec)
  File "<frozen importlib._bootstrap>", line 696, in _load
  File "<frozen importlib._bootstrap>", line 677, in _load_unlocked
  File "<frozen importlib._bootstrap_external>", line 728, in exec_module
  File "<frozen importlib._bootstrap>", line 219, in _call_with_frames_removed
  File "main.py", line 1, in <module>
    from flask import Flask
ModuleNotFoundError: No module named 'flask'
[UID:2390][3045068] Child process with pid: 3045077 was killed by signal: 15, core dump: 0
[UID:2390][3045068] Child process with pid: 3045149 was killed by signal: 15, core dump: 0
[UID:2390][3045068] Child process with pid: 3045952 was killed by signal: 15, core dump: 0
[UID:2390][3045068] Child process with pid: 3048922 was killed by signal: 15, core dump: 0
Traceback (most recent call last):
  File "/home/convertimageio/public_html/app-flask/passenger_wsgi.py", line 8, in <module>
    wsgi = imp.load_source('wsgi', 'main.py')
  File "/opt/alt/python37/lib64/python3.7/imp.py", line 171, in load_source
    module = _load(spec)
  File "<frozen importlib._bootstrap>", line 696, in _load
  File "<frozen importlib._bootstrap>", line 677, in _load_unlocked
  File "<frozen importlib._bootstrap_external>", line 728, in exec_module
  File "<frozen importlib._bootstrap>", line 219, in _call_with_frames_removed
  File "main.py", line 1, in <module>
    from flask import Flask
ModuleNotFoundError: No module named 'flask'
[UID:2390][3049956] Child process with pid: 3049977 was killed by signal: 15, core dump: 0
[UID:2390][3049956] Child process with pid: 3055133 was killed by signal: 15, core dump: 0
Traceback (most recent call last):
  File "/home/convertimageio/public_html/app-flask/passenger_wsgi.py", line 8, in <module>
    wsgi = imp.load_source('wsgi', 'main.py')
  File "/opt/alt/python37/lib64/python3.7/imp.py", line 171, in load_source
    module = _load(spec)
  File "<frozen importlib._bootstrap>", line 696, in _load
  File "<frozen importlib._bootstrap>", line 677, in _load_unlocked
  File "<frozen importlib._bootstrap_external>", line 728, in exec_module
  File "<frozen importlib._bootstrap>", line 219, in _call_with_frames_removed
  File "main.py", line 1, in <module>
    from flask import Flask
ModuleNotFoundError: No module named 'flask'
Traceback (most recent call last):
  File "/home/convertimageio/public_html/app-flask/passenger_wsgi.py", line 8, in <module>
    wsgi = imp.load_source('wsgi', 'main.py')
  File "/opt/alt/python37/lib64/python3.7/imp.py", line 171, in load_source
    module = _load(spec)
  File "<frozen importlib._bootstrap>", line 696, in _load
  File "<frozen importlib._bootstrap>", line 677, in _load_unlocked
  File "<frozen importlib._bootstrap_external>", line 728, in exec_module
  File "<frozen importlib._bootstrap>", line 219, in _call_with_frames_removed
  File "main.py", line 1, in <module>
    from flask import Flask
ModuleNotFoundError: No module named 'flask'
[2024-01-06 15:29:48,315] ERROR in app: Exception on / [GET]
Traceback (most recent call last):
  File "/home/convertimageio/virtualenv/public_html/app-flask/3.7/lib/python3.7/site-packages/flask/app.py", line 2073, in wsgi_app
    response = self.full_dispatch_request()
  File "/home/convertimageio/virtualenv/public_html/app-flask/3.7/lib/python3.7/site-packages/flask/app.py", line 1518, in full_dispatch_request
    rv = self.handle_user_exception(e)
  File "/home/convertimageio/virtualenv/public_html/app-flask/3.7/lib/python3.7/site-packages/flask/app.py", line 1516, in full_dispatch_request
    rv = self.dispatch_request()
  File "/home/convertimageio/virtualenv/public_html/app-flask/3.7/lib/python3.7/site-packages/flask/app.py", line 1502, in dispatch_request
    return self.ensure_sync(self.view_functions[rule.endpoint])(**req.view_args)
  File "main.py", line 21, in hello
    return render_template('index.html', images=images)
  File "/home/convertimageio/virtualenv/public_html/app-flask/3.7/lib/python3.7/site-packages/flask/templating.py", line 150, in render_template
    ctx.app,
  File "/home/convertimageio/virtualenv/public_html/app-flask/3.7/lib/python3.7/site-packages/flask/templating.py", line 128, in _render
    rv = template.render(context)
  File "/home/convertimageio/virtualenv/public_html/app-flask/3.7/lib/python3.7/site-packages/jinja2/environment.py", line 1291, in render
    self.environment.handle_exception()
  File "/home/convertimageio/virtualenv/public_html/app-flask/3.7/lib/python3.7/site-packages/jinja2/environment.py", line 926, in handle_exception
    raise rewrite_traceback_stack(source=source)
  File "/home/convertimageio/public_html/app-flask/templates/index.html", line 37, in top-level template code
    <form action="{{url_for('upload_file')}}"  id="form"  method="POST" enctype="multipart/form-data">
  File "/home/convertimageio/virtualenv/public_html/app-flask/3.7/lib/python3.7/site-packages/flask/helpers.py", line 338, in url_for
    return appctx.app.handle_url_build_error(error, endpoint, values)
  File "/home/convertimageio/virtualenv/public_html/app-flask/3.7/lib/python3.7/site-packages/flask/helpers.py", line 326, in url_for
    endpoint, values, method=method, force_external=external
  File "/home/convertimageio/virtualenv/public_html/app-flask/3.7/lib/python3.7/site-packages/werkzeug/routing.py", line 2315, in build
    raise BuildError(endpoint, values, method, self)
werkzeug.routing.BuildError: Could not build url for endpoint 'upload_file'. Did you mean 'hello' instead?
[2024-01-06 15:29:55,307] ERROR in app: Exception on / [GET]
Traceback (most recent call last):
  File "/home/convertimageio/virtualenv/public_html/app-flask/3.7/lib/python3.7/site-packages/flask/app.py", line 2073, in wsgi_app
    response = self.full_dispatch_request()
  File "/home/convertimageio/virtualenv/public_html/app-flask/3.7/lib/python3.7/site-packages/flask/app.py", line 1518, in full_dispatch_request
    rv = self.handle_user_exception(e)
  File "/home/convertimageio/virtualenv/public_html/app-flask/3.7/lib/python3.7/site-packages/flask/app.py", line 1516, in full_dispatch_request
    rv = self.dispatch_request()
  File "/home/convertimageio/virtualenv/public_html/app-flask/3.7/lib/python3.7/site-packages/flask/app.py", line 1502, in dispatch_request
    return self.ensure_sync(self.view_functions[rule.endpoint])(**req.view_args)
  File "main.py", line 21, in hello
    return render_template('index.html', images=images)
  File "/home/convertimageio/virtualenv/public_html/app-flask/3.7/lib/python3.7/site-packages/flask/templating.py", line 150, in render_template
    ctx.app,
  File "/home/convertimageio/virtualenv/public_html/app-flask/3.7/lib/python3.7/site-packages/flask/templating.py", line 128, in _render
    rv = template.render(context)
  File "/home/convertimageio/virtualenv/public_html/app-flask/3.7/lib/python3.7/site-packages/jinja2/environment.py", line 1291, in render
    self.environment.handle_exception()
  File "/home/convertimageio/virtualenv/public_html/app-flask/3.7/lib/python3.7/site-packages/jinja2/environment.py", line 926, in handle_exception
    raise rewrite_traceback_stack(source=source)
  File "/home/convertimageio/public_html/app-flask/templates/index.html", line 37, in top-level template code
    <form action="{{url_for('upload_file')}}"  id="form"  method="POST" enctype="multipart/form-data">
  File "/home/convertimageio/virtualenv/public_html/app-flask/3.7/lib/python3.7/site-packages/flask/helpers.py", line 338, in url_for
    return appctx.app.handle_url_build_error(error, endpoint, values)
  File "/home/convertimageio/virtualenv/public_html/app-flask/3.7/lib/python3.7/site-packages/flask/helpers.py", line 326, in url_for
    endpoint, values, method=method, force_external=external
  File "/home/convertimageio/virtualenv/public_html/app-flask/3.7/lib/python3.7/site-packages/werkzeug/routing.py", line 2315, in build
    raise BuildError(endpoint, values, method, self)
werkzeug.routing.BuildError: Could not build url for endpoint 'upload_file'. Did you mean 'hello' instead?
[2024-01-06 15:30:14,289] ERROR in app: Exception on / [GET]
Traceback (most recent call last):
  File "/home/convertimageio/virtualenv/public_html/app-flask/3.7/lib/python3.7/site-packages/flask/app.py", line 2073, in wsgi_app
    response = self.full_dispatch_request()
  File "/home/convertimageio/virtualenv/public_html/app-flask/3.7/lib/python3.7/site-packages/flask/app.py", line 1518, in full_dispatch_request
    rv = self.handle_user_exception(e)
  File "/home/convertimageio/virtualenv/public_html/app-flask/3.7/lib/python3.7/site-packages/flask/app.py", line 1516, in full_dispatch_request
    rv = self.dispatch_request()
  File "/home/convertimageio/virtualenv/public_html/app-flask/3.7/lib/python3.7/site-packages/flask/app.py", line 1502, in dispatch_request
    return self.ensure_sync(self.view_functions[rule.endpoint])(**req.view_args)
  File "main.py", line 21, in hello
    return render_template('index.html', images=images)
  File "/home/convertimageio/virtualenv/public_html/app-flask/3.7/lib/python3.7/site-packages/flask/templating.py", line 150, in render_template
    ctx.app,
  File "/home/convertimageio/virtualenv/public_html/app-flask/3.7/lib/python3.7/site-packages/flask/templating.py", line 128, in _render
    rv = template.render(context)
  File "/home/convertimageio/virtualenv/public_html/app-flask/3.7/lib/python3.7/site-packages/jinja2/environment.py", line 1291, in render
    self.environment.handle_exception()
  File "/home/convertimageio/virtualenv/public_html/app-flask/3.7/lib/python3.7/site-packages/jinja2/environment.py", line 926, in handle_exception
    raise rewrite_traceback_stack(source=source)
  File "/home/convertimageio/public_html/app-flask/templates/index.html", line 37, in top-level template code
    <form action="{{url_for('upload_file')}}"  id="form"  method="POST" enctype="multipart/form-data">
  File "/home/convertimageio/virtualenv/public_html/app-flask/3.7/lib/python3.7/site-packages/flask/helpers.py", line 338, in url_for
    return appctx.app.handle_url_build_error(error, endpoint, values)
  File "/home/convertimageio/virtualenv/public_html/app-flask/3.7/lib/python3.7/site-packages/flask/helpers.py", line 326, in url_for
    endpoint, values, method=method, force_external=external
  File "/home/convertimageio/virtualenv/public_html/app-flask/3.7/lib/python3.7/site-packages/werkzeug/routing.py", line 2315, in build
    raise BuildError(endpoint, values, method, self)
werkzeug.routing.BuildError: Could not build url for endpoint 'upload_file'. Did you mean 'hello' instead?
[UID:2390][3069438] Child process with pid: 3069455 was killed by signal: 15, core dump: 0
